Workbook

Sheet Leia-me
B1: Painel Comercial: pipeline, metas e carteira
B2: Modelo em Excel para apoiar o time comercial. Todos os nomes, valores e datas são fictícios e foram criados para demonstração.
B4: Para que serve
B5: Metas | C5: Mostra o quanto cada consultor vendeu contra a meta do mês e do ano.
B6: Pipeline | C6: Soma as oportunidades abertas por etapa e calcula o forecast ponderado pela probabilidade de cada etapa.
B7: Ação | C7: Aponta oportunidades paradas, previsões de fechamento vencidas e clientes que precisam de contato.
B9: Como usar
B10: 1. Painel | C10: Escolha o mês e o consultor nas células amarelas do topo. Todos os números e gráficos acompanham o filtro.
B11: 2. Oportunidades | C11: Registre cada oportunidade em uma linha nova (até a linha 604). Escolha cliente, consultor, produto e etapa nas listas. Região, probabilidade, valor ponderado, status, dias e alerta são calculados.
B12: 3. Metas | C12: Digite a meta mensal de cada consultor. Os totais são somados sozinhos.
B13: 4. Carteira | C13: Cadastre os clientes. Última compra, total comprado e situação (Ativo, Em risco, Inativo ou Sem compra) saem das vendas ganhas.
B14: 5. Parâmetros | C14: Ajuste a data de referência, os limites de dias e a probabilidade de cada etapa.
B16: Legenda de cores
B17: Texto azul | C17: Valor digitado por você (entrada).
B18: Texto preto | C18: Fórmula. Não precisa editar.
B19: Texto verde | C19: Vínculo com outra aba.
B20: Fundo amarelo | C20: Campo que você mais vai alterar: filtros do Painel e parâmetros principais.
B22: Regras de cálculo
B23: Valor ponderado | C23: Valor da oportunidade x probabilidade da etapa (aba Parâmetros).
B24: Atingimento | C24: Realizado do mês dividido pela meta do mês. Realizado considera só oportunidades ganhas, pela data de fechamento.
B25: Conversão | C25: Oportunidades ganhas dividido por ganhas mais perdidas, em todo o período.
B26: Parada | C26: Oportunidade aberta há mais dias que o limite da aba Parâmetros (45 dias de partida).
B27: Previsão vencida | C27: Oportunidade aberta cuja data prevista de fechamento já passou em relação à data de referência.
B28: Situação do cliente | C28: Dias desde a última venda ganha até a data de referência: até 90 dias é Ativo, até 180 é Em risco, acima disso é Inativo.
B30: Premissas
B31: Data de referência | C31: Fixada em 13/10/2026 para o painel não mudar sozinho. Em uso real, troque por =HOJE() em Parâmetros.
B32: Dados | C32: Clientes, consultores, valores e metas são inventados. Para usar dados reais, exporte as oportunidades do CRM e cole nas colunas azuis de Oportunidades.
B33: Capacidade | C33: Oportunidades aceita até 600 linhas e Carteira até 100 clientes. Para mais, copie as fórmulas das últimas linhas para baixo e amplie os nomes definidos.

Sheet Painel
B1: Painel Comercial
B2: Pipeline, metas e carteira de clientes. Escolha o mês e o consultor nas células amarelas. Dados fictícios para demonstração.
B4: Mês | C4: 46266 | E4: Consultor | F4: Todos | H4: Data de referência | I4: =DataRef -> 46308
B6: META DO MÊS | D6: VENDIDO NO MÊS | F6: ATINGIMENTO DA META | H6: PIPELINE ABERTO | J6: FORECAST PONDERADO | L6: CONVERSÃO
B7: =IF($F$4="Todos",INDEX(Metas!$C$11:$N$11,MATCH(MesIni,Metas!$C$4:$N$4,0)),INDEX(Metas!$C$5:$N$10,MATCH($F$4,Metas!$A$5:$A$10,0),MATCH(MesIni,Metas!$C$4:$N$4,0))) -> 355000 | D7: =SUMIFS(op_Valor,op_Status,"Ganha",op_Consultor,CritConsultor,op_Fech,">="&MesIni,op_Fech,"<="&MesFim) -> 221600 | F7: =IFERROR(D7/B7,0) -> 0.62422535 | H7: =SUMIFS(op_Valor,op_Status,"Aberta",op_Consultor,CritConsultor) -> 1623700 | J7: =SUMIFS(op_Pond,op_Status,"Aberta",op_Consultor,CritConsultor) -> 749005 | L7: =IFERROR(COUNTIFS(op_Status,"Ganha",op_Consultor,CritConsultor)/(COUNTIFS(op_Status,"Ganha",op_Consultor,CritConsultor)+COUNTIFS(op_Status,"Perdida",op_Consultor,CritConsultor)),0) -> 0.57854406
B8: para o filtro atual | D8: oportunidades ganhas | F8: =IF(F7>=1,"Meta batida",IF(F7>=0.8,"Quase lá","Abaixo da meta")) -> Abaixo da meta | H8: soma das oportunidades abertas | J8: valor x probabilidade da etapa | L8: ganhas / fechadas, todo o período
B10: Meta x realizado por consultor (mês selecionado)
B11: Consultor | C11: Meta (R$) | D11: Realizado (R$) | E11: Atingimento | F11: Realizado - meta (R$) | G11: Situação
B12: =Parâmetros!$E$18 -> Ana Souza | C12: =INDEX(Metas!$C$5:$N$10,MATCH($B12,Metas!$A$5:$A$10,0),MATCH(MesIni,Metas!$C$4:$N$4,0)) -> 81000 | D12: =SUMIFS(op_Valor,op_Status,"Ganha",op_Consultor,$B12,op_Fech,">="&MesIni,op_Fech,"<="&MesFim) -> 8300 | E12: =IFERROR(D12/C12,0) -> 0.10246914 | F12: =D12-C12 -> -72700 | G12: =IF(E12>=1,"Meta batida",IF(E12>=0.8,"Quase lá","Abaixo")) -> Abaixo
B13: =Parâmetros!$E$19 -> Bruno Lima | C13: =INDEX(Metas!$C$5:$N$10,MATCH($B13,Metas!$A$5:$A$10,0),MATCH(MesIni,Metas!$C$4:$N$4,0)) -> 68000 | D13: =SUMIFS(op_Valor,op_Status,"Ganha",op_Consultor,$B13,op_Fech,">="&MesIni,op_Fech,"<="&MesFim) -> 43400 | E13: =IFERROR(D13/C13,0) -> 0.63823529 | F13: =D13-C13 -> -24600 | G13: =IF(E13>=1,"Meta batida",IF(E13>=0.8,"Quase lá","Abaixo")) -> Abaixo
B14: =Parâmetros!$E$20 -> Carla Mendes | C14: =INDEX(Metas!$C$5:$N$10,MATCH($B14,Metas!$A$5:$A$10,0),MATCH(MesIni,Metas!$C$4:$N$4,0)) -> 55000 | D14: =SUMIFS(op_Valor,op_Status,"Ganha",op_Consultor,$B14,op_Fech,">="&MesIni,op_Fech,"<="&MesFim) -> 22900 | E14: =IFERROR(D14/C14,0) -> 0.41636364 | F14: =D14-C14 -> -32100 | G14: =IF(E14>=1,"Meta batida",IF(E14>=0.8,"Quase lá","Abaixo")) -> Abaixo
B15: =Parâmetros!$E$21 -> Diego Rocha | C15: =INDEX(Metas!$C$5:$N$10,MATCH($B15,Metas!$A$5:$A$10,0),MATCH(MesIni,Metas!$C$4:$N$4,0)) -> 45000 | D15: =SUMIFS(op_Valor,op_Status,"Ganha",op_Consultor,$B15,op_Fech,">="&MesIni,op_Fech,"<="&MesFim) -> 61600 | E15: =IFERROR(D15/C15,0) -> 1.3688889 | F15: =D15-C15 -> 16600 | G15: =IF(E15>=1,"Meta batida",IF(E15>=0.8,"Quase lá","Abaixo")) -> Meta batida
B16: =Parâmetros!$E$22 -> Elisa Prado | C16: =INDEX(Metas!$C$5:$N$10,MATCH($B16,Metas!$A$5:$A$10,0),MATCH(MesIni,Metas!$C$4:$N$4,0)) -> 48000 | D16: =SUMIFS(op_Valor,op_Status,"Ganha",op_Consultor,$B16,op_Fech,">="&MesIni,op_Fech,"<="&MesFim) -> 35000 | E16: =IFERROR(D16/C16,0) -> 0.72916667 | F16: =D16-C16 -> -13000 | G16: =IF(E16>=1,"Meta batida",IF(E16>=0.8,"Quase lá","Abaixo")) -> Abaixo
B17: =Parâmetros!$E$23 -> Felipe Duarte | C17: =INDEX(Metas!$C$5:$N$10,MATCH($B17,Metas!$A$5:$A$10,0),MATCH(MesIni,Metas!$C$4:$N$4,0)) -> 58000 | D17: =SUMIFS(op_Valor,op_Status,"Ganha",op_Consultor,$B17,op_Fech,">="&MesIni,op_Fech,"<="&MesFim) -> 50400 | E17: =IFERROR(D17/C17,0) -> 0.86896552 | F17: =D17-C17 -> -7600 | G17: =IF(E17>=1,"Meta batida",IF(E17>=0.8,"Quase lá","Abaixo")) -> Quase lá
B18: Total da equipe | C18: =SUM(C12:C17) -> 355000 | D18: =SUM(D12:D17) -> 221600 | E18: =IFERROR(D18/C18,0) -> 0.62422535 | F18: =D18-C18 -> -133400 | G18: =IF(E18>=1,"Meta batida",IF(E18>=0.8,"Quase lá","Abaixo")) -> Abaixo
B20: Alertas e indicadores (segue o filtro de consultor)
B21: Indicador | E21: Qtde | F21: Valor (R$)
B22: ="Oportunidades paradas (mais de "&DiasParada&" dias)" -> Oportunidades paradas (mais de 45 dias) | E22: =COUNTIFS(op_Alerta,"Parada",op_Consultor,CritConsultor) -> 14 | F22: =SUMIFS(op_Valor,op_Alerta,"Parada",op_Consultor,CritConsultor) -> 245400
B23: Previsão de fechamento vencida | E23: =COUNTIFS(op_Alerta,"Previsão vencida",op_Consultor,CritConsultor) -> 33 | F23: =SUMIFS(op_Valor,op_Alerta,"Previsão vencida",op_Consultor,CritConsultor) -> 700800
B24: Clientes em risco (histórico comprado) | E24: =COUNTIFS(cl_Situacao,"Em risco",cl_Consultor,CritConsultor) -> 8 | F24: =SUMIFS(cl_Total,cl_Situacao,"Em risco",cl_Consultor,CritConsultor) -> 476400
B25: Clientes inativos (histórico comprado) | E25: =COUNTIFS(cl_Situacao,"Inativo",cl_Consultor,CritConsultor) -> 2 | F25: =SUMIFS(cl_Total,cl_Situacao,"Inativo",cl_Consultor,CritConsultor) -> 79900
B26: Ticket médio das vendas ganhas | E26: =COUNTIFS(op_Status,"Ganha",op_Consultor,CritConsultor) -> 151 | F26: =IFERROR(AVERAGEIFS(op_Valor,op_Status,"Ganha",op_Consultor,CritConsultor),0) -> 21873.51
B27: Ciclo médio de venda (dias) | E27: =IFERROR(AVERAGEIFS(op_Dias,op_Status,"Ganha",op_Consultor,CritConsultor),0) -> 43.245033
B29: Funil de oportunidades abertas
B30: Etapa | C30: Qtde | D30: Valor (R$) | E30: Ponderado (R$) | F30: % do pipeline
B31: =Parâmetros!$B$17 -> Prospecção | C31: =COUNTIFS(op_Etapa,$B31,op_Consultor,CritConsultor) -> 14 | D31: =SUMIFS(op_Valor,op_Etapa,$B31,op_Consultor,CritConsultor) -> 222300 | E31: =SUMIFS(op_Pond,op_Etapa,$B31,op_Consultor,CritConsultor) -> 22230 | F31: =IFERROR(D31/D$35,0) -> 0.13690953
B32: =Parâmetros!$B$18 -> Qualificação | C32: =COUNTIFS(op_Etapa,$B32,op_Consultor,CritConsultor) -> 24 | D32: =SUMIFS(op_Valor,op_Etapa,$B32,op_Consultor,CritConsultor) -> 474500 | E32: =SUMIFS(op_Pond,op_Etapa,$B32,op_Consultor,CritConsultor) -> 118625 | F32: =IFERROR(D32/D$35,0) -> 0.29223379
B33: =Parâmetros!$B$19 -> Proposta enviada | C33: =COUNTIFS(op_Etapa,$B33,op_Consultor,CritConsultor) -> 21 | D33: =SUMIFS(op_Valor,op_Etapa,$B33,op_Consultor,CritConsultor) -> 348100 | E33: =SUMIFS(op_Pond,op_Etapa,$B33,op_Consultor,CritConsultor) -> 174050 | F33: =IFERROR(D33/D$35,0) -> 0.21438689
B34: =Parâmetros!$B$20 -> Negociação | C34: =COUNTIFS(op_Etapa,$B34,op_Consultor,CritConsultor) -> 22 | D34: =SUMIFS(op_Valor,op_Etapa,$B34,op_Consultor,CritConsultor) -> 578800 | E34: =SUMIFS(op_Pond,op_Etapa,$B34,op_Consultor,CritConsultor) -> 434100 | F34: =IFERROR(D34/D$35,0) -> 0.35646979
B35: Total em aberto | C35: =SUM(C31:C34) -> 81 | D35: =SUM(D31:D34) -> 1623700 | E35: =SUM(E31:E34) -> 749005 | F35: =SUM(F31:F34) -> 1
B37: Top 5 clientes por valor comprado (toda a carteira)
B38: Cliente | D38: Total comprado (R$) | E38: Última compra | F38: Situação | G38: Consultor
B39: =1&". "&INDEX(cl_Nome,MATCH(LARGE(cl_Chave,1),cl_Chave,0)) -> 1. Prefeitura de Campo Alto | D39: =INDEX(cl_Total,MATCH(LARGE(cl_Chave,1),cl_Chave,0)) -> 305800 | E39: =INDEX(cl_Ultima,MATCH(LARGE(cl_Chave,1),cl_Chave,0)) -> 46303 | F39: =INDEX(cl_Situacao,MATCH(LARGE(cl_Chave,1),cl_Chave,0)) -> Ativo | G39: =INDEX(cl_Consultor,MATCH(LARGE(cl_Chave,1),cl_Chave,0)) -> Ana Souza
B40: =2&". "&INDEX(cl_Nome,MATCH(LARGE(cl_Chave,2),cl_Chave,0)) -> 2. Rede Primeiros Passos | D40: =INDEX(cl_Total,MATCH(LARGE(cl_Chave,2),cl_Chave,0)) -> 295400 | E40: =INDEX(cl_Ultima,MATCH(LARGE(cl_Chave,2),cl_Chave,0)) -> 46256 | F40: =INDEX(cl_Situacao,MATCH(LARGE(cl_Chave,2),cl_Chave,0)) -> Ativo | G40: =INDEX(cl_Consultor,MATCH(LARGE(cl_Chave,2),cl_Chave,0)) -> Diego Rocha
B41: =3&". "&INDEX(cl_Nome,MATCH(LARGE(cl_Chave,3),cl_Chave,0)) -> 3. Instituto Aprender+ | D41: =INDEX(cl_Total,MATCH(LARGE(cl_Chave,3),cl_Chave,0)) -> 262100 | E41: =INDEX(cl_Ultima,MATCH(LARGE(cl_Chave,3),cl_Chave,0)) -> 46216 | F41: =INDEX(cl_Situacao,MATCH(LARGE(cl_Chave,3),cl_Chave,0)) -> Em risco | G41: =INDEX(cl_Consultor,MATCH(LARGE(cl_Chave,3),cl_Chave,0)) -> Carla Mendes
B42: =4&". "&INDEX(cl_Nome,MATCH(LARGE(cl_Chave,4),cl_Chave,0)) -> 4. Prefeitura de Monte Belo | D42: =INDEX(cl_Total,MATCH(LARGE(cl_Chave,4),cl_Chave,0)) -> 260400 | E42: =INDEX(cl_Ultima,MATCH(LARGE(cl_Chave,4),cl_Chave,0)) -> 46235 | F42: =INDEX(cl_Situacao,MATCH(LARGE(cl_Chave,4),cl_Chave,0)) -> Ativo | G42: =INDEX(cl_Consultor,MATCH(LARGE(cl_Chave,4),cl_Chave,0)) -> Ana Souza
B43: =5&". "&INDEX(cl_Nome,MATCH(LARGE(cl_Chave,5),cl_Chave,0)) -> 5. Centro Educacional Pioneiro | D43: =INDEX(cl_Total,MATCH(LARGE(cl_Chave,5),cl_Chave,0)) -> 241500 | E43: =INDEX(cl_Ultima,MATCH(LARGE(cl_Chave,5),cl_Chave,0)) -> 46243 | F43: =INDEX(cl_Situacao,MATCH(LARGE(cl_Chave,5),cl_Chave,0)) -> Ativo | G43: =INDEX(cl_Consultor,MATCH(LARGE(cl_Chave,5),cl_Chave,0)) -> Felipe Duarte
B46: Vendas por mês, 2026 (segue o filtro de consultor)
B47: Mês | C47: Meta | D47: Realizado | E47: Atingimento | F47: Realizado - meta
B48: =Parâmetros!$N$17 -> Jan/26 | C48: =IF($F$4="Todos",INDEX(Metas!$C$11:$N$11,MATCH(Parâmetros!$M$17,Metas!$C$4:$N$4,0)),INDEX(Metas!$C$5:$N$10,MATCH($F$4,Metas!$A$5:$A$10,0),MATCH(Parâmetros!$M$17,Metas!$C$4:$N$4,0))) -> 270000 | D48: =SUMIFS(op_Valor,op_Status,"Ganha",op_Consultor,CritConsultor,op_Fech,">="&Parâmetros!$M$17,op_Fech,"<="&EOMONTH(Parâmetros!$M$17,0)) -> 249500 | E48: =IF(Parâmetros!$M$17>DataRef,"",IFERROR(D48/C48,0)) -> 0.92407407 | F48: =IF(Parâmetros!$M$17>DataRef,"",D48-C48) -> -20500
...

Sheet Oportunidades
A1: Oportunidades
A2: Cada linha é uma oportunidade do CRM. Digite nas colunas azuis até a linha 604. Colunas pretas são fórmulas. Todos os dados são fictícios.
A4: ID | B4: Criação | C4: Cliente | D4: Consultor | E4: Região | F4: Produto | G4: Etapa | H4: Valor (R$) | I4: Prob. | J4: Ponderado (R$) | K4: Previsão de fechamento | L4: Fechamento | M4: Status | N4: Dias (aberta ou ciclo) | O4: Alerta
A5: OP-0001 | B5: 45931 | C5: Colégio Maristela | D5: Diego Rocha | E5: =IF(C5="","",IFERROR(INDEX(cl_Regiao,MATCH(C5,cl_Nome,0)),"")) -> Sudeste | F5: Material Complementar | G5: Fechado perdido | H5: 2000 | I5: =IF(G5="","",IFERROR(INDEX(pr_Prob,MATCH(G5,pr_Etapa,0)),0)) -> 0 | J5: =IF(H5="","",H5*I5) -> 0 | L5: 45997 | M5: =IF(G5="","",IF(G5="Fechado ganho","Ganha",IF(G5="Fechado perdido","Perdida","Aberta"))) -> Perdida | N5: =IF(B5="","",IF(M5="Aberta",DataRef-B5,IF(L5="","",L5-B5))) -> 66 | O5: =IF(M5<>"Aberta","",IF(AND(K5<>"",K5<DataRef),"Previsão vencida",IF(N5>DiasParada,"Parada","")))
A6: OP-0002 | B6: 45931 | C6: Cursinho Meta Certa | D6: Felipe Duarte | E6: =IF(C6="","",IFERROR(INDEX(cl_Regiao,MATCH(C6,cl_Nome,0)),"")) -> Norte | F6: Coleção Didática | G6: Fechado ganho | H6: 31500 | I6: =IF(G6="","",IFERROR(INDEX(pr_Prob,MATCH(G6,pr_Etapa,0)),0)) -> 1 | J6: =IF(H6="","",H6*I6) -> 31500 | L6: 45996 | M6: =IF(G6="","",IF(G6="Fechado ganho","Ganha",IF(G6="Fechado perdido","Perdida","Aberta"))) -> Ganha | N6: =IF(B6="","",IF(M6="Aberta",DataRef-B6,IF(L6="","",L6-B6))) -> 65 | O6: =IF(M6<>"Aberta","",IF(AND(K6<>"",K6<DataRef),"Previsão vencida",IF(N6>DiasParada,"Parada","")))
A7: OP-0003 | B7: 45932 | C7: Colégio Integral Plus | D7: Ana Souza | E7: =IF(C7="","",IFERROR(INDEX(cl_Regiao,MATCH(C7,cl_Nome,0)),"")) -> Sudeste | F7: Material Complementar | G7: Fechado ganho | H7: 10400 | I7: =IF(G7="","",IFERROR(INDEX(pr_Prob,MATCH(G7,pr_Etapa,0)),0)) -> 1 | J7: =IF(H7="","",H7*I7) -> 10400 | L7: 45962 | M7: =IF(G7="","",IF(G7="Fechado ganho","Ganha",IF(G7="Fechado perdido","Perdida","Aberta"))) -> Ganha | N7: =IF(B7="","",IF(M7="Aberta",DataRef-B7,IF(L7="","",L7-B7))) -> 30 | O7: =IF(M7<>"Aberta","",IF(AND(K7<>"",K7<DataRef),"Previsão vencida",IF(N7>DiasParada,"Parada","")))
A8: OP-0004 | B8: 45933 | C8: Prefeitura de Campo Alto | D8: Ana Souza | E8: =IF(C8="","",IFERROR(INDEX(cl_Regiao,MATCH(C8,cl_Nome,0)),"")) -> Sudeste | F8: Formação de Professores | G8: Fechado perdido | H8: 17200 | I8: =IF(G8="","",IFERROR(INDEX(pr_Prob,MATCH(G8,pr_Etapa,0)),0)) -> 0 | J8: =IF(H8="","",H8*I8) -> 0 | L8: 45993 | M8: =IF(G8="","",IF(G8="Fechado ganho","Ganha",IF(G8="Fechado perdido","Perdida","Aberta"))) -> Perdida | N8: =IF(B8="","",IF(M8="Aberta",DataRef-B8,IF(L8="","",L8-B8))) -> 60 | O8: =IF(M8<>"Aberta","",IF(AND(K8<>"",K8<DataRef),"Previsão vencida",IF(N8>DiasParada,"Parada","")))
A9: OP-0005 | B9: 45935 | C9: Colégio Maristela | D9: Diego Rocha | E9: =IF(C9="","",IFERROR(INDEX(cl_Regiao,MATCH(C9,cl_Nome,0)),"")) -> Sudeste | F9: Formação de Professores | G9: Proposta enviada | H9: 12400 | I9: =IF(G9="","",IFERROR(INDEX(pr_Prob,MATCH(G9,pr_Etapa,0)),0)) -> 0.5 | J9: =IF(H9="","",H9*I9) -> 6200 | K9: 46028 | M9: =IF(G9="","",IF(G9="Fechado ganho","Ganha",IF(G9="Fechado perdido","Perdida","Aberta"))) -> Aberta | N9: =IF(B9="","",IF(M9="Aberta",DataRef-B9,IF(L9="","",L9-B9))) -> 373 | O9: =IF(M9<>"Aberta","",IF(AND(K9<>"",K9<DataRef),"Previsão vencida",IF(N9>DiasParada,"Parada",""))) -> Previsão vencida
A10: OP-0006 | B10: 45935 | C10: Rede Saber Mais | D10: Bruno Lima | E10: =IF(C10="","",IFERROR(INDEX(cl_Regiao,MATCH(C10,cl_Nome,0)),"")) -> Sul | F10: Plataforma Digital | G10: Fechado perdido | H10: 41800 | I10: =IF(G10="","",IFERROR(INDEX(pr_Prob,MATCH(G10,pr_Etapa,0)),0)) -> 0 | J10: =IF(H10="","",H10*I10) -> 0 | L10: 45947 | M10: =IF(G10="","",IF(G10="Fechado ganho","Ganha",IF(G10="Fechado perdido","Perdida","Aberta"))) -> Perdida | N10: =IF(B10="","",IF(M10="Aberta",DataRef-B10,IF(L10="","",L10-B10))) -> 12 | O10: =IF(M10<>"Aberta","",IF(AND(K10<>"",K10<DataRef),"Previsão vencida",IF(N10>DiasParada,"Parada","")))
A11: OP-0007 | B11: 45937 | C11: Escola Alicerce | D11: Elisa Prado | E11: =IF(C11="","",IFERROR(INDEX(cl_Regiao,MATCH(C11,cl_Nome,0)),"")) -> Centro-Oeste | F11: Formação de Professores | G11: Fechado ganho | H11: 12700 | I11: =IF(G11="","",IFERROR(INDEX(pr_Prob,MATCH(G11,pr_Etapa,0)),0)) -> 1 | J11: =IF(H11="","",H11*I11) -> 12700 | L11: 45991 | M11: =IF(G11="","",IF(G11="Fechado ganho","Ganha",IF(G11="Fechado perdido","Perdida","Aberta"))) -> Ganha | N11: =IF(B11="","",IF(M11="Aberta",DataRef-B11,IF(L11="","",L11-B11))) -> 54 | O11: =IF(M11<>"Aberta","",IF(AND(K11<>"",K11<DataRef),"Previsão vencida",IF(N11>DiasParada,"Parada","")))
A12: OP-0008 | B12: 45938 | C12: Prefeitura de Monte Belo | D12: Ana Souza | E12: =IF(C12="","",IFERROR(INDEX(cl_Regiao,MATCH(C12,cl_Nome,0)),"")) -> Sudeste | F12: Plataforma Digital | G12: Fechado ganho | H12: 56800 | I12: =IF(G12="","",IFERROR(INDEX(pr_Prob,MATCH(G12,pr_Etapa,0)),0)) -> 1 | J12: =IF(H12="","",H12*I12) -> 56800 | L12: 45962 | M12: =IF(G12="","",IF(G12="Fechado ganho","Ganha",IF(G12="Fechado perdido","Perdida","Aberta"))) -> Ganha | N12: =IF(B12="","",IF(M12="Aberta",DataRef-B12,IF(L12="","",L12-B12))) -> 24 | O12: =IF(M12<>"Aberta","",IF(AND(K12<>"",K12<DataRef),"Previsão vencida",IF(N12>DiasParada,"Parada","")))
A13: OP-0009 | B13: 45939 | C13: Colégio Aurora | D13: Ana Souza | E13: =IF(C13="","",IFERROR(INDEX(cl_Regiao,MATCH(C13,cl_Nome,0)),"")) -> Sudeste | F13: Coleção Didática | G13: Fechado ganho | H13: 8400 | I13: =IF(G13="","",IFERROR(INDEX(pr_Prob,MATCH(G13,pr_Etapa,0)),0)) -> 1 | J13: =IF(H13="","",H13*I13) -> 8400 | L13: 45967 | M13: =IF(G13="","",IF(G13="Fechado ganho","Ganha",IF(G13="Fechado perdido","Perdida","Aberta"))) -> Ganha | N13: =IF(B13="","",IF(M13="Aberta",DataRef-B13,IF(L13="","",L13-B13))) -> 28 | O13: =IF(M13<>"Aberta","",IF(AND(K13<>"",K13<DataRef),"Previsão vencida",IF(N13>DiasParada,"Parada","")))
A14: OP-0010 | B14: 45940 | C14: Colégio Estrela do Norte | D14: Felipe Duarte | E14: =IF(C14="","",IFERROR(INDEX(cl_Regiao,MATCH(C14,cl_Nome,0)),"")) -> Norte | F14: Coleção Didática | G14: Fechado perdido | H14: 52900 | I14: =IF(G14="","",IFERROR(INDEX(pr_Prob,MATCH(G14,pr_Etapa,0)),0)) -> 0 | J14: =IF(H14="","",H14*I14) -> 0 | L14: 45957 | M14: =IF(G14="","",IF(G14="Fechado ganho","Ganha",IF(G14="Fechado perdido","Perdida","Aberta"))) -> Perdida | N14: =IF(B14="","",IF(M14="Aberta",DataRef-B14,IF(L14="","",L14-B14))) -> 17 | O14: =IF(M14<>"Aberta","",IF(AND(K14<>"",K14<DataRef),"Previsão vencida",IF(N14>DiasParada,"Parada","")))
A15: OP-0011 | B15: 45940 | C15: Colégio Ipê Amarelo | D15: Elisa Prado | E15: =IF(C15="","",IFERROR(INDEX(cl_Regiao,MATCH(C15,cl_Nome,0)),"")) -> Centro-Oeste | F15: Formação de Professores | G15: Fechado ganho | H15: 7700 | I15: =IF(G15="","",IFERROR(INDEX(pr_Prob,MATCH(G15,pr_Etapa,0)),0)) -> 1 | J15: =IF(H15="","",H15*I15) -> 7700 | L15: 45975 | M15: =IF(G15="","",IF(G15="Fechado ganho","Ganha",IF(G15="Fechado perdido","Perdida","Aberta"))) -> Ganha | N15: =IF(B15="","",IF(M15="Aberta",DataRef-B15,IF(L15="","",L15-B15))) -> 35 | O15: =IF(M15<>"Aberta","",IF(AND(K15<>"",K15<DataRef),"Previsão vencida",IF(N15>DiasParada,"Parada","")))
A16: OP-0012 | B16: 45940 | C16: Rede Primeiros Passos | D16: Diego Rocha | E16: =IF(C16="","",IFERROR(INDEX(cl_Regiao,MATCH(C16,cl_Nome,0)),"")) -> Sudeste | F16: Coleção Didática | G16: Fechado ganho | H16: 77800 | I16: =IF(G16="","",IFERROR(INDEX(pr_Prob,MATCH(G16,pr_Etapa,0)),0)) -> 1 | J16: =IF(H16="","",H16*I16) -> 77800 | L16: 45977 | M16: =IF(G16="","",IF(G16="Fechado ganho","Ganha",IF(G16="Fechado perdido","Perdida","Aberta"))) -> Ganha | N16: =IF(B16="","",IF(M16="Aberta",DataRef-B16,IF(L16="","",L16-B16))) -> 37 | O16: =IF(M16<>"Aberta","",IF(AND(K16<>"",K16<DataRef),"Previsão vencida",IF(N16>DiasParada,"Parada","")))
A17: OP-0013 | B17: 45942 | C17: Rede Saber Mais | D17: Bruno Lima | E17: =IF(C17="","",IFERROR(INDEX(cl_Regiao,MATCH(C17,cl_Nome,0)),"")) -> Sul | F17: Coleção Didática | G17: Fechado perdido | H17: 25400 | I17: =IF(G17="","",IFERROR(INDEX(pr_Prob,MATCH(G17,pr_Etapa,0)),0)) -> 0 | J17: =IF(H17="","",H17*I17) -> 0 | L17: 45994 | M17: =IF(G17="","",IF(G17="Fechado ganho","Ganha",IF(G17="Fechado perdido","Perdida","Aberta"))) -> Perdida | N17: =IF(B17="","",IF(M17="Aberta",DataRef-B17,IF(L17="","",L17-B17))) -> 52 | O17: =IF(M17<>"Aberta","",IF(AND(K17<>"",K17<DataRef),"Previsão vencida",IF(N17>DiasParada,"Parada","")))
A18: OP-0014 | B18: 45943 | C18: Rede Primeiros Passos | D18: Diego Rocha | E18: =IF(C18="","",IFERROR(INDEX(cl_Regiao,MATCH(C18,cl_Nome,0)),"")) -> Sudeste | F18: Material Complementar | G18: Fechado ganho | H18: 12000 | I18: =IF(G18="","",IFERROR(INDEX(pr_Prob,MATCH(G18,pr_Etapa,0)),0)) -> 1 | J18: =IF(H18="","",H18*I18) -> 12000 | L18: 46009 | M18: =IF(G18="","",IF(G18="Fechado ganho","Ganha",IF(G18="Fechado perdido","Perdida","Aberta"))) -> Ganha | N18: =IF(B18="","",IF(M18="Aberta",DataRef-B18,IF(L18="","",L18-B18))) -> 66 | O18: =IF(M18<>"Aberta","",IF(AND(K18<>"",K18<DataRef),"Previsão vencida",IF(N18>DiasParada,"Parada","")))
A19: OP-0015 | B19: 45945 | C19: Centro Educacional Pioneiro | D19: Felipe Duarte | E19: =IF(C19="","",IFERROR(INDEX(cl_Regiao,MATCH(C19,cl_Nome,0)),"")) -> Norte | F19: Material Complementar | G19: Fechado perdido | H19: 7100 | I19: =IF(G19="","",IFERROR(INDEX(pr_Prob,MATCH(G19,pr_Etapa,0)),0)) -> 0 | J19: =IF(H19="","",H19*I19) -> 0 | L19: 45969 | M19: =IF(G19="","",IF(G19="Fechado ganho","Ganha",IF(G19="Fechado perdido","Perdida","Aberta"))) -> Perdida | N19: =IF(B19="","",IF(M19="Aberta",DataRef-B19,IF(L19="","",L19-B19))) -> 24 | O19: =IF(M19<>"Aberta","",IF(AND(K19<>"",K19<DataRef),"Previsão vencida",IF(N19>DiasParada,"Parada","")))
A20: OP-0016 | B20: 45945 | C20: Colégio Estrela do Norte | D20: Felipe Duarte | E20: =IF(C20="","",IFERROR(INDEX(cl_Regiao,MATCH(C20,cl_Nome,0)),"")) -> Norte | F20: Formação de Professores | G20: Fechado ganho | H20: 8100 | I20: =IF(G20="","",IFERROR(INDEX(pr_Prob,MATCH(G20,pr_Etapa,0)),0)) -> 1 | J20: =IF(H20="","",H20*I20) -> 8100 | L20: 46007 | M20: =IF(G20="","",IF(G20="Fechado ganho","Ganha",IF(G20="Fechado perdido","Perdida","Aberta"))) -> Ganha | N20: =IF(B20="","",IF(M20="Aberta",DataRef-B20,IF(L20="","",L20-B20))) -> 62 | O20: =IF(M20<>"Aberta","",IF(AND(K20<>"",K20<DataRef),"Previsão vencida",IF(N20>DiasParada,"Parada","")))
A21: OP-0017 | B21: 45946 | C21: Instituto Novo Rumo | D21: Diego Rocha | E21: =IF(C21="","",IFERROR(INDEX(cl_Regiao,MATCH(C21,cl_Nome,0)),"")) -> Sudeste | F21: Plataforma Digital | G21: Fechado perdido | H21: 33700 | I21: =IF(G21="","",IFERROR(INDEX(pr_Prob,MATCH(G21,pr_Etapa,0)),0)) -> 0 | J21: =IF(H21="","",H21*I21) -> 0 | L21: 46018 | M21: =IF(G21="","",IF(G21="Fechado ganho","Ganha",IF(G21="Fechado perdido","Perdida","Aberta"))) -> Perdida | N21: =IF(B21="","",IF(M21="Aberta",DataRef-B21,IF(L21="","",L21-B21))) -> 72 | O21: =IF(M21<>"Aberta","",IF(AND(K21<>"",K21<DataRef),"Previsão vencida",IF(N21>DiasParada,"Parada","")))
... A26: OP-0022 | B26: 45950 | C26: Escola Girassol | D26: Bruno Lima | E26: =IF(C26="","",IFERROR(INDEX(cl_Regiao,MATCH(C26,cl_Nome,0)),"")) -> Sul | F26: Material Complementar | G26: Fechado ganho | H26: 11900 | I26: =IF(G26="","",IFERROR(INDEX(pr_Prob,MATCH(G26,pr_Etapa,0)),0)) -> 1 | J26: =IF(H26="","",H26*I26) -> 11900 | L26: 45962 | M26: =IF(G26="","",IF(G26="Fechado ganho","Ganha",IF(G26="Fechado perdido","Perdida","Aberta"))) -> Ganha | N26: =IF(B26="","",IF(M26="Aberta",DataRef-B26,IF(L26="","",L26-B26))) -> 12 | O26: =IF(M26<>"Aberta","",IF(AND(K26<>"",K26<DataRef),"Previsão vencida",IF(N26>DiasParada,"Parada","")))
A27: OP-0023 | B27: 45954 | C27: Colégio Estrela do Norte | D27: Felipe Duarte | E27: =IF(C27="","",IFERROR(INDEX(cl_Regiao,MATCH(C27,cl_Nome,0)),"")) -> Norte | F27: Material Complementar | G27: Proposta enviada | H27: 2800 | I27: =IF(G27="","",IFERROR(INDEX(pr_Prob,MATCH(G27,pr_Etapa,0)),0)) -> 0.5 | J27: =IF(H27="","",H27*I27) -> 1400 | K27: 46030 | M27: =IF(G27="","",IF(G27="Fechado ganho","Ganha",IF(G27="Fechado perdido","Perdida","Aberta"))) -> Aberta | N27: =IF(B27="","",IF(M27="Aberta",DataRef-B27,IF(L27="","",L27-B27))) -> 354 | O27: =IF(M27<>"Aberta","",IF(AND(K27<>"",K27<DataRef),"Previsão vencida",IF(N27>DiasParada,"Parada",""))) -> Previsão vencida
A28: OP-0024 | B28: 45955 | C28: Escola Árvore da Vida | D28: Elisa Prado | E28: =IF(C28="","",IFERROR(INDEX(cl_Regiao,MATCH(C28,cl_Nome,0)),"")) -> Centro-Oeste | F28: Formação de Professores | G28: Fechado ganho | H28: 10500 | I28: =IF(G28="","",IFERROR(INDEX(pr_Prob,MATCH(G28,pr_Etapa,0)),0)) -> 1 | J28: =IF(H28="","",H28*I28) -> 10500 | L28: 45992 | M28: =IF(G28="","",IF(G28="Fechado ganho","Ganha",IF(G28="Fechado perdido","Perdida","Aberta"))) -> Ganha | N28: =IF(B28="","",IF(M28="Aberta",DataRef-B28,IF(L28="","",L28-B28))) -> 37 | O28: =IF(M28<>"Aberta","",IF(AND(K28<>"",K28<DataRef),"Previsão vencida",IF(N28>DiasParada,"Parada","")))
A29: OP-0025 | B29: 45957 | C29: Cursinho Meta Certa | D29: Felipe Duarte | E29: =IF(C29="","",IFERROR(INDEX(cl_Regiao,MATCH(C29,cl_Nome,0)),"")) -> Norte | F29: Coleção Didática | G29: Fechado ganho | H29: 27900 | I29: =IF(G29="","",IFERROR(INDEX(pr_Prob,MATCH(G29,pr_Etapa,0)),0)) -> 1 | J29: =IF(H29="","",H29*I29) -> 27900 | L29: 46008 | M29: =IF(G29="","",IF(G29="Fechado ganho","Ganha",IF(G29="Fechado perdido","Perdida","Aberta"))) -> Ganha | N29: =IF(B29="","",IF(M29="Aberta",DataRef-B29,IF(L29="","",L29-B29))) -> 51 | O29: =IF(M29<>"Aberta","",IF(AND(K29<>"",K29<DataRef),"Previsão vencida",IF(N29>DiasParada,"Parada","")))
A30: OP-0026 | B30: 45957 | C30: Rede Primeiros Passos | D30: Diego Rocha | E30: =IF(C30="","",IFERROR(INDEX(cl_Regiao,MATCH(C30,cl_Nome,0)),"")) -> Sudeste | F30: Material Complementar | G30: Fechado perdido | H30: 7000 | I30: =IF(G30="","",IFERROR(INDEX(pr_Prob,MATCH(G30,pr_Etapa,0)),0)) -> 0 | J30: =IF(H30="","",H30*I30) -> 0 | L30: 46003 | M30: =IF(G30="","",IF(G30="Fechado ganho","Ganha",IF(G30="Fechado perdido","Perdida","Aberta"))) -> Perdida | N30: =IF(B30="","",IF(M30="Aberta",DataRef-B30,IF(L30="","",L30-B30))) -> 46 | O30: =IF(M30<>"Aberta","",IF(AND(K30<>"",K30<DataRef),"Previsão vencida",IF(N30>DiasParada,"Parada","")))
A31: OP-0027 | B31: 45959 | C31: Escola Caminho do Saber | D31: Elisa Prado | E31: =IF(C31="","",IFERROR(INDEX(cl_Regiao,MATCH(C31,cl_Nome,0)),"")) -> Centro-Oeste | F31: Coleção Didática | G31: Fechado ganho | H31: 9300 | I31: =IF(G31="","",IFERROR(INDEX(pr_Prob,MATCH(G31,pr_Etapa,0)),0)) -> 1 | J31: =IF(H31="","",H31*I31) -> 9300 | L31: 45986 | M31: =IF(G31="","",IF(G31="Fechado ganho","Ganha",IF(G31="Fechado perdido","Perdida","Aberta"))) -> Ganha | N31: =IF(B31="","",IF(M31="Aberta",DataRef-B31,IF(L31="","",L31-B31))) -> 27 | O31: =IF(M31<>"Aberta","",IF(AND(K31<>"",K31<DataRef),"Previsão vencida",IF(N31>DiasParada,"Parada","")))
A32: OP-0028 | B32: 45959 | C32: Instituto Aprender+ | D32: Carla Mendes | E32: =IF(C32="","",IFERROR(INDEX(cl_Regiao,MATCH(C32,cl_Nome,0)),"")) -> Nordeste | F32: Coleção Didática | G32: Fechado ganho | H32: 94700 | I32: =IF(G32="","",IFERROR(INDEX(pr_Prob,MATCH(G32,pr_Etapa,0)),0)) -> 1 | J32: =IF(H32="","",H32*I32) -> 94700 | L32: 46011 | M32: =IF(G32="","",IF(G32="Fechado ganho","Ganha",IF(G32="Fechado perdido","Perdida","Aberta"))) -> Ganha | N32: =IF(B32="","",IF(M32="Aberta",DataRef-B32,IF(L32="","",L32-B32))) -> 52 | O32: =IF(M32<>"Aberta","",IF(AND(K32<>"",K32<DataRef),"Previsão vencida",IF(N32>DiasParada,"Parada","")))
A33: OP-0029 | B33: 45959 | C33: Prefeitura de Monte Belo | D33: Ana Souza | E33: =IF(C33="","",IFERROR(INDEX(cl_Regiao,MATCH(C33,cl_Nome,0)),"")) -> Sudeste | F33: Material Complementar | G33: Fechado ganho | H33: 5600 | I33: =IF(G33="","",IFERROR(INDEX(pr_Prob,MATCH(G33,pr_Etapa,0)),0)) -> 1 | J33: =IF(H33="","",H33*I33) -> 5600 | L33: 46031 | M33: =IF(G33="","",IF(G33="Fechado ganho","Ganha",IF(G33="Fechado perdido","Perdida","Aberta"))) -> Ganha | N33: =IF(B33="","",IF(M33="Aberta",DataRef-B33,IF(L33="","",L33-B33))) -> 72 | O33: =IF(M33<>"Aberta","",IF(AND(K33<>"",K33<DataRef),"Previsão vencida",IF(N33>DiasParada,"Parada","")))
A34: OP-0030 | B34: 45960 | C34: Escola Nova Era | D34: Bruno Lima | E34: =IF(C34="","",IFERROR(INDEX(cl_Regiao,MATCH(C34,cl_Nome,0)),"")) -> Sul | F34: Material Complementar | G34: Fechado perdido | H34: 5100 | I34: =IF(G34="","",IFERROR(INDEX(pr_Prob,MATCH(G34,pr_Etapa,0)),0)) -> 0 | J34: =IF(H34="","",H34*I34) -> 0 | L34: 46004 | M34: =IF(G34="","",IF(G34="Fechado ganho","Ganha",IF(G34="Fechado perdido","Perdida","Aberta"))) -> Perdida | N34: =IF(B34="","",IF(M34="Aberta",DataRef-B34,IF(L34="","",L34-B34))) -> 44 | O34: =IF(M34<>"Aberta","",IF(AND(K34<>"",K34<DataRef),"Previsão vencida",IF(N34>DiasParada,"Parada","")))
A35: OP-0031 | B35: 45961 | C35: Centro Educacional Pioneiro | D35: Felipe Duarte | E35: =IF(C35="","",IFERROR(INDEX(cl_Regiao,MATCH(C35,cl_Nome,0)),"")) -> Norte | F35: Coleção Didática | G35: Fechado ganho | H35: 40300 | I35: =IF(G35="","",IFERROR(INDEX(pr_Prob,MATCH(G35,pr_Etapa,0)),0)) -> 1 | J35: =IF(H35="","",H35*I35) -> 40300 | L35: 46037 | M35: =IF(G35="","",IF(G35="Fechado ganho","Ganha",IF(G35="Fechado perdido","Perdida","Aberta"))) -> Ganha | N35: =IF(B35="","",IF(M35="Aberta",DataRef-B35,IF(L35="","",L35-B35))) -> 76 | O35: =IF(M35<>"Aberta","",IF(AND(K35<>"",K35<DataRef),"Previsão vencida",IF(N35>DiasParada,"Parada","")))
A36: OP-0032 | B36: 45961 | C36: Colégio Lumiar | D36: Carla Mendes | E36: =IF(C36="","",IFERROR(INDEX(cl_Regiao,MATCH(C36,cl_Nome,0)),"")) -> Nordeste | F36: Material Complementar | G36: Fechado perdido | H36: 10700 | I36: =IF(G36="","",IFERROR(INDEX(pr_Prob,MATCH(G36,pr_Etapa,0)),0)) -> 0 | J36: =IF(H36="","",H36*I36) -> 0 | L36: 46011 | M36: =IF(G36="","",IF(G36="Fechado ganho","Ganha",IF(G36="Fechado perdido","Perdida","Aberta"))) -> Perdida | N36: =IF(B36="","",IF(M36="Aberta",DataRef-B36,IF(L36="","",L36-B36))) -> 50 | O36: =IF(M36<>"Aberta","",IF(AND(K36<>"",K36<DataRef),"Previsão vencida",IF(N36>DiasParada,"Parada","")))
A37: OP-0033 | B37: 45962 | C37: Rede Primeiros Passos | D37: Diego Rocha | E37: =IF(C37="","",IFERROR(INDEX(cl_Regiao,MATCH(C37,cl_Nome,0)),"")) -> Sudeste | F37: Material Complementar | G37: Fechado ganho | H37: 13700 | I37: =IF(G37="","",IFERROR(INDEX(pr_Prob,MATCH(G37,pr_Etapa,0)),0)) -> 1 | J37: =IF(H37="","",H37*I37) -> 13700 | L37: 46006 | M37: =IF(G37="","",IF(G37="Fechado ganho","Ganha",IF(G37="Fechado perdido","Perdida","Aberta"))) -> Ganha | N37: =IF(B37="","",IF(M37="Aberta",DataRef-B37,IF(L37="","",L37-B37))) -> 44 | O37: =IF(M37<>"Aberta","",IF(AND(K37<>"",K37<DataRef),"Previsão vencida",IF(N37>DiasParada,"Parada","")))
A38: OP-0034 | B38: 45963 | C38: Instituto Novo Rumo | D38: Diego Rocha | E38: =IF(C38="","",IFERROR(INDEX(cl_Regiao,MATCH(C38,cl_Nome,0)),"")) -> Sudeste | F38: Material Complementar | G38: Fechado ganho | H38: 22500 | I38: =IF(G38="","",IFERROR(INDEX(pr_Prob,MATCH(G38,pr_Etapa,0)),0)) -> 1 | J38: =IF(H38="","",H38*I38) -> 22500 | L38: 45987 | M38: =IF(G38="","",IF(G38="Fechado ganho","Ganha",IF(G38="Fechado perdido","Perdida","Aberta"))) -> Ganha | N38: =IF(B38="","",IF(M38="Aberta",DataRef-B38,IF(L38="","",L38-B38))) -> 24 | O38: =IF(M38<>"Aberta","",IF(AND(K38<>"",K38<DataRef),"Previsão vencida",IF(N38>DiasParada,"Parada","")))
A39: OP-0035 | B39: 45963 | C39: Prefeitura de Vila Nova | D39: Felipe Duarte | E39: =IF(C39="","",IFERROR(INDEX(cl_Regiao,MATCH(C39,cl_Nome,0)),"")) -> Norte | F39: Formação de Professores | G39: Fechado perdido | H39: 12500 | I39: =IF(G39="","",IFERROR(INDEX(pr_Prob,MATCH(G39,pr_Etapa,0)),0)) -> 0 | J39: =IF(H39="","",H39*I39) -> 0 | L39: 46001 | M39: =IF(G39="","",IF(G39="Fechado ganho","Ganha",IF(G39="Fechado perdido","Perdida","Aberta"))) -> Perdida | N39: =IF(B39="","",IF(M39="Aberta",DataRef-B39,IF(L39="","",L39-B39))) -> 38 | O39: =IF(M39<>"Aberta","",IF(AND(K39<>"",K39<DataRef),"Previsão vencida",IF(N39>DiasParada,"Parada","")))
... A80: OP-0076 | B80: 46007 | C80: Colégio Santa Clara | D80: Diego Rocha | E80: =IF(C80="","",IFERROR(INDEX(cl_Regiao,MATCH(C80,cl_Nome,0)),"")) -> Sudeste | F80: Formação de Professores | G80: Fechado perdido | H80: 7200 | I80: =IF(G80="","",IFERROR(INDEX(pr_Prob,MATCH(G80,pr_Etapa,0)),0)) -> 0 | J80: =IF(H80="","",H80*I80) -> 0 | L80: 46080 | M80: =IF(G80="","",IF(G80="Fechado ganho","Ganha",IF(G80="Fechado perdido","Perdida","Aberta"))) -> Perdida | N80: =IF(B80="","",IF(M80="Aberta",DataRef-B80,IF(L80="","",L80-B80))) -> 73 | O80: =IF(M80<>"Aberta","",IF(AND(K80<>"",K80<DataRef),"Previsão vencida",IF(N80>DiasParada,"Parada","")))
A81: OP-0077 | B81: 46007 | C81: Prefeitura de Vila Nova | D81: Felipe Duarte | E81: =IF(C81="","",IFERROR(INDEX(cl_Regiao,MATCH(C81,cl_Nome,0)),"")) -> Norte | F81: Material Complementar | G81: Qualificação | H81: 15200 | I81: =IF(G81="","",IFERROR(INDEX(pr_Prob,MATCH(G81,pr_Etapa,0)),0)) -> 0.25 | J81: =IF(H81="","",H81*I81) -> 3800 | K81: 46060 | M81: =IF(G81="","",IF(G81="Fechado ganho","Ganha",IF(G81="Fechado perdido","Perdida","Aberta"))) -> Aberta | N81: =IF(B81="","",IF(M81="Aberta",DataRef-B81,IF(L81="","",L81-B81))) -> 301 | O81: =IF(M81<>"Aberta","",IF(AND(K81<>"",K81<DataRef),"Previsão vencida",IF(N81>DiasParada,"Parada",""))) -> Previsão vencida
A82: OP-0078 | B82: 46008 | C82: Escola Girassol | D82: Bruno Lima | E82: =IF(C82="","",IFERROR(INDEX(cl_Regiao,MATCH(C82,cl_Nome,0)),"")) -> Sul | F82: Material Complementar | G82: Fechado perdido | H82: 7700 | I82: =IF(G82="","",IFERROR(INDEX(pr_Prob,MATCH(G82,pr_Etapa,0)),0)) -> 0 | J82: =IF(H82="","",H82*I82) -> 0 | L82: 46049 | M82: =IF(G82="","",IF(G82="Fechado ganho","Ganha",IF(G82="Fechado perdido","Perdida","Aberta"))) -> Perdida | N82: =IF(B82="","",IF(M82="Aberta",DataRef-B82,IF(L82="","",L82-B82))) -> 41 | O82: =IF(M82<>"Aberta","",IF(AND(K82<>"",K82<DataRef),"Previsão vencida",IF(N82>DiasParada,"Parada","")))
A83: OP-0079 | B83: 46008 | C83: Escola Nova Era | D83: Bruno Lima | E83: =IF(C83="","",IFERROR(INDEX(cl_Regiao,MATCH(C83,cl_Nome,0)),"")) -> Sul | F83: Formação de Professores | G83: Fechado perdido | H83: 4700 | I83: =IF(G83="","",IFERROR(INDEX(pr_Prob,MATCH(G83,pr_Etapa,0)),0)) -> 0 | J83: =IF(H83="","",H83*I83) -> 0 | L83: 46033 | M83: =IF(G83="","",IF(G83="Fechado ganho","Ganha",IF(G83="Fechado perdido","Perdida","Aberta"))) -> Perdida | N83: =IF(B83="","",IF(M83="Aberta",DataRef-B83,IF(L83="","",L83-B83))) -> 25 | O83: =IF(M83<>"Aberta","",IF(AND(K83<>"",K83<DataRef),"Previsão vencida",IF(N83>DiasParada,"Parada","")))
A84: OP-0080 | B84: 46010 | C84: Colégio Aurora | D84: Ana Souza | E84: =IF(C84="","",IFERROR(INDEX(cl_Regiao,MATCH(C84,cl_Nome,0)),"")) -> Sudeste | F84: Formação de Professores | G84: Fechado ganho | H84: 11200 | I84: =IF(G84="","",IFERROR(INDEX(pr_Prob,MATCH(G84,pr_Etapa,0)),0)) -> 1 | J84: =IF(H84="","",H84*I84) -> 11200 | L84: 46043 | M84: =IF(G84="","",IF(G84="Fechado ganho","Ganha",IF(G84="Fechado perdido","Perdida","Aberta"))) -> Ganha | N84: =IF(B84="","",IF(M84="Aberta",DataRef-B84,IF(L84="","",L84-B84))) -> 33 | O84: =IF(M84<>"Aberta","",IF(AND(K84<>"",K84<DataRef),"Previsão vencida",IF(N84>DiasParada,"Parada","")))
A85: OP-0081 | B85: 46011 | C85: Colégio Integral Plus | D85: Ana Souza | E85: =IF(C85="","",IFERROR(INDEX(cl_Regiao,MATCH(C85,cl_Nome,0)),"")) -> Sudeste | F85: Material Complementar | G85: Fechado perdido | H85: 8600 | I85: =IF(G85="","",IFERROR(INDEX(pr_Prob,MATCH(G85,pr_Etapa,0)),0)) -> 0 | J85: =IF(H85="","",H85*I85) -> 0 | L85: 46038 | M85: =IF(G85="","",IF(G85="Fechado ganho","Ganha",IF(G85="Fechado perdido","Perdida","Aberta"))) -> Perdida | N85: =IF(B85="","",IF(M85="Aberta",DataRef-B85,IF(L85="","",L85-B85))) -> 27 | O85: =IF(M85<>"Aberta","",IF(AND(K85<>"",K85<DataRef),"Previsão vencida",IF(N85>DiasParada,"Parada","")))
...

Sheet Metas
A1: Metas de vendas por consultor, 2026
A2: Digite a meta mensal de cada consultor (azul). Os totais e o Painel se atualizam sozinhos. Metas fictícias.
A4: Consultor | B4: Meta do ano (R$) | C4: =Parâmetros!$M$17 -> 46023 | D4: =Parâmetros!$M$18 -> 46054 | E4: =Parâmetros!$M$19 -> 46082 | F4: =Parâmetros!$M$20 -> 46113 | G4: =Parâmetros!$M$21 -> 46143 | H4: =Parâmetros!$M$22 -> 46174 | I4: =Parâmetros!$M$23 -> 46204 | J4: =Parâmetros!$M$24 -> 46235 | K4: =Parâmetros!$M$25 -> 46266 | L4: =Parâmetros!$M$26 -> 46296 | M4: =Parâmetros!$M$27 -> 46327 | N4: =Parâmetros!$M$28 -> 46357
A5: =Parâmetros!$E$18 -> Ana Souza | B5: =SUM(C5:N5) -> 857000 | C5: 58000 | D5: 62000 | E5: 75000 | F5: 64000 | G5: 69000 | H5: 72000 | I5: 62000 | J5: 84000 | K5: 81000 | L5: 74000 | M5: 85000 | N5: 71000
A6: =Parâmetros!$E$19 -> Bruno Lima | B6: =SUM(C6:N6) -> 684000 | C6: 51000 | D6: 54000 | E6: 62000 | F6: 60000 | G6: 61000 | H6: 53000 | I6: 48000 | J6: 57000 | K6: 68000 | L6: 59000 | M6: 58000 | N6: 53000
A7: =Parâmetros!$E$20 -> Carla Mendes | B7: =SUM(C7:N7) -> 656000 | C7: 44000 | D7: 50000 | E7: 63000 | F7: 56000 | G7: 54000 | H7: 50000 | I7: 46000 | J7: 57000 | K7: 55000 | L7: 60000 | M7: 67000 | N7: 54000
A8: =Parâmetros!$E$21 -> Diego Rocha | B8: =SUM(C8:N8) -> 541000 | C8: 38000 | D8: 43000 | E8: 50000 | F8: 43000 | G8: 49000 | H8: 41000 | I8: 42000 | J8: 48000 | K8: 45000 | L8: 53000 | M8: 48000 | N8: 41000
A9: =Parâmetros!$E$22 -> Elisa Prado | B9: =SUM(C9:N9) -> 484000 | C9: 32000 | D9: 37000 | E9: 39000 | F9: 40000 | G9: 40000 | H9: 38000 | I9: 32000 | J9: 40000 | K9: 48000 | L9: 45000 | M9: 49000 | N9: 44000
A10: =Parâmetros!$E$23 -> Felipe Duarte | B10: =SUM(C10:N10) -> 633000 | C10: 47000 | D10: 55000 | E10: 54000 | F10: 50000 | G10: 53000 | H10: 53000 | I10: 43000 | J10: 53000 | K10: 58000 | L10: 52000 | M10: 67000 | N10: 48000
A11: Total da equipe | B11: =SUM(B5:B10) -> 3855000 | C11: =SUM(C5:C10) -> 270000 | D11: =SUM(D5:D10) -> 301000 | E11: =SUM(E5:E10) -> 343000 | F11: =SUM(F5:F10) -> 313000 | G11: =SUM(G5:G10) -> 326000 | H11: =SUM(H5:H10) -> 307000 | I11: =SUM(I5:I10) -> 273000 | ... N11: =SUM(N5:N10) -> 311000
A13: Valores em R$. Sazonalidade fictícia: fevereiro, março, agosto e o último trimestre pesam mais.

Sheet Carteira
A1: Carteira de clientes
A2: Cadastre os clientes nas colunas azuis. Última compra, total comprado e situação saem das vendas ganhas em Oportunidades.
A4: Cliente | B4: Segmento | C4: Região | D4: Consultor | E4: Última compra | F4: Nº de compras | G4: Total comprado (R$) | H4: Dias sem comprar | I4: Situação | J4: Ação sugerida | K4: Chave de ranking
A5: Colégio Aurora | B5: Escola privada | C5: Sudeste | D5: Ana Souza | E5: =IF(A5="","",IF(F5=0,"",_xlfn.MAXIFS(op_Fech,op_Cliente,A5,op_Status,"Ganha"))) -> 46266 | F5: =IF(A5="","",COUNTIFS(op_Cliente,A5,op_Status,"Ganha")) -> 8 | G5: =IF(A5="","",SUMIFS(op_Valor,op_Cliente,A5,op_Status,"Ganha")) -> 104600 | H5: =IF(OR(A5="",E5=""),"",DataRef-E5) -> 42 | I5: =IF(A5="","",IF(F5=0,"Sem compra",IF(H5<=DiasRisco,"Ativo",IF(H5<=DiasInativo,"Em risco","Inativo")))) -> Ativo | J5: =IF(A5="","",IF(I5="Ativo","Manter relacionamento e oferecer upsell",IF(I5="Em risco","Contato do consultor nesta semana",IF(I5="Inativo","Campanha de reativação","Primeira abordagem comercial")))) -> Manter relacionamento e oferecer upsell | K5: =IF(A5="","",G5+ROW()/1000000) -> 104600
A6: Escola Nova Era | B6: Escola privada | C6: Sul | D6: Bruno Lima | E6: =IF(A6="","",IF(F6=0,"",_xlfn.MAXIFS(op_Fech,op_Cliente,A6,op_Status,"Ganha"))) -> 46284 | F6: =IF(A6="","",COUNTIFS(op_Cliente,A6,op_Status,"Ganha")) -> 4 | G6: =IF(A6="","",SUMIFS(op_Valor,op_Cliente,A6,op_Status,"Ganha")) -> 52600 | H6: =IF(OR(A6="",E6=""),"",DataRef-E6) -> 24 | I6: =IF(A6="","",IF(F6=0,"Sem compra",IF(H6<=DiasRisco,"Ativo",IF(H6<=DiasInativo,"Em risco","Inativo")))) -> Ativo | J6: =IF(A6="","",IF(I6="Ativo","Manter relacionamento e oferecer upsell",IF(I6="Em risco","Contato do consultor nesta semana",IF(I6="Inativo","Campanha de reativação","Primeira abordagem comercial")))) -> Manter relacionamento e oferecer upsell | K6: =IF(A6="","",G6+ROW()/1000000) -> 52600
A7: Instituto Horizonte | B7: Rede de ensino | C7: Nordeste | D7: Carla Mendes | E7: =IF(A7="","",IF(F7=0,"",_xlfn.MAXIFS(op_Fech,op_Cliente,A7,op_Status,"Ganha"))) -> 46193 | F7: =IF(A7="","",COUNTIFS(op_Cliente,A7,op_Status,"Ganha")) -> 2 | G7: =IF(A7="","",SUMIFS(op_Valor,op_Cliente,A7,op_Status,"Ganha")) -> 29600 | H7: =IF(OR(A7="",E7=""),"",DataRef-E7) -> 115 | I7: =IF(A7="","",IF(F7=0,"Sem compra",IF(H7<=DiasRisco,"Ativo",IF(H7<=DiasInativo,"Em risco","Inativo")))) -> Em risco | J7: =IF(A7="","",IF(I7="Ativo","Manter relacionamento e oferecer upsell",IF(I7="Em risco","Contato do consultor nesta semana",IF(I7="Inativo","Campanha de reativação","Primeira abordagem comercial")))) -> Contato do consultor nesta semana | K7: =IF(A7="","",G7+ROW()/1000000) -> 29600
A8: Colégio Santa Clara | B8: Escola privada | C8: Sudeste | D8: Diego Rocha | E8: =IF(A8="","",IF(F8=0,"",_xlfn.MAXIFS(op_Fech,op_Cliente,A8,op_Status,"Ganha"))) -> 46235 | F8: =IF(A8="","",COUNTIFS(op_Cliente,A8,op_Status,"Ganha")) -> 5 | G8: =IF(A8="","",SUMIFS(op_Valor,op_Cliente,A8,op_Status,"Ganha")) -> 36600 | H8: =IF(OR(A8="",E8=""),"",DataRef-E8) -> 73 | I8: =IF(A8="","",IF(F8=0,"Sem compra",IF(H8<=DiasRisco,"Ativo",IF(H8<=DiasInativo,"Em risco","Inativo")))) -> Ativo | J8: =IF(A8="","",IF(I8="Ativo","Manter relacionamento e oferecer upsell",IF(I8="Em risco","Contato do consultor nesta semana",IF(I8="Inativo","Campanha de reativação","Primeira abordagem comercial")))) -> Manter relacionamento e oferecer upsell | K8: =IF(A8="","",G8+ROW()/1000000) -> 36600
A9: Escola Alicerce | B9: Escola privada | C9: Centro-Oeste | D9: Elisa Prado | E9: =IF(A9="","",IF(F9=0,"",_xlfn.MAXIFS(op_Fech,op_Cliente,A9,op_Status,"Ganha"))) -> 46206 | F9: =IF(A9="","",COUNTIFS(op_Cliente,A9,op_Status,"Ganha")) -> 4 | G9: =IF(A9="","",SUMIFS(op_Valor,op_Cliente,A9,op_Status,"Ganha")) -> 28700 | H9: =IF(OR(A9="",E9=""),"",DataRef-E9) -> 102 | I9: =IF(A9="","",IF(F9=0,"Sem compra",IF(H9<=DiasRisco,"Ativo",IF(H9<=DiasInativo,"Em risco","Inativo")))) -> Em risco | J9: =IF(A9="","",IF(I9="Ativo","Manter relacionamento e oferecer upsell",IF(I9="Em risco","Contato do consultor nesta semana",IF(I9="Inativo","Campanha de reativação","Primeira abordagem comercial")))) -> Contato do consultor nesta semana | K9: =IF(A9="","",G9+ROW()/1000000) -> 28700
A10: Centro Educacional Pioneiro | B10: Rede de ensino | C10: Norte | D10: Felipe Duarte | E10: =IF(A10="","",IF(F10=0,"",_xlfn.MAXIFS(op_Fech,op_Cliente,A10,op_Status,"Ganha"))) -> 46243 | F10: =IF(A10="","",COUNTIFS(op_Cliente,A10,op_Status,"Ganha")) -> 6 | G10: =IF(A10="","",SUMIFS(op_Valor,op_Cliente,A10,op_Status,"Ganha")) -> 241500 | H10: =IF(OR(A10="",E10=""),"",DataRef-E10) -> 65 | I10: =IF(A10="","",IF(F10=0,"Sem compra",IF(H10<=DiasRisco,"Ativo",IF(H10<=DiasInativo,"Em risco","Inativo")))) -> Ativo | J10: =IF(A10="","",IF(I10="Ativo","Manter relacionamento e oferecer upsell",IF(I10="Em risco","Contato do consultor nesta semana",IF(I10="Inativo","Campanha de reativação","Primeira abordagem comercial")))) -> Manter relacionamento e oferecer upsell | K10: =IF(A10="","",G10+ROW()/1000000) -> 241500
A11: Colégio Vale Verde | B11: Escola privada | C11: Sudeste | D11: Ana Souza | E11: =IF(A11="","",IF(F11=0,"",_xlfn.MAXIFS(op_Fech,op_Cliente,A11,op_Status,"Ganha"))) -> 46237 | F11: =IF(A11="","",COUNTIFS(op_Cliente,A11,op_Status,"Ganha")) -> 6 | G11: =IF(A11="","",SUMIFS(op_Valor,op_Cliente,A11,op_Status,"Ganha")) -> 39900 | H11: =IF(OR(A11="",E11=""),"",DataRef-E11) -> 71 | I11: =IF(A11="","",IF(F11=0,"Sem compra",IF(H11<=DiasRisco,"Ativo",IF(H11<=DiasInativo,"Em risco","Inativo")))) -> Ativo | J11: =IF(A11="","",IF(I11="Ativo","Manter relacionamento e oferecer upsell",IF(I11="Em risco","Contato do consultor nesta semana",IF(I11="Inativo","Campanha de reativação","Primeira abordagem comercial")))) -> Manter relacionamento e oferecer upsell | K11: =IF(A11="","",G11+ROW()/1000000) -> 39900
A12: Escola Girassol | B12: Escola privada | C12: Sul | D12: Bruno Lima | E12: =IF(A12="","",IF(F12=0,"",_xlfn.MAXIFS(op_Fech,op_Cliente,A12,op_Status,"Ganha"))) -> 46169 | F12: =IF(A12="","",COUNTIFS(op_Cliente,A12,op_Status,"Ganha")) -> 2 | G12: =IF(A12="","",SUMIFS(op_Valor,op_Cliente,A12,op_Status,"Ganha")) -> 16700 | H12: =IF(OR(A12="",E12=""),"",DataRef-E12) -> 139 | I12: =IF(A12="","",IF(F12=0,"Sem compra",IF(H12<=DiasRisco,"Ativo",IF(H12<=DiasInativo,"Em risco","Inativo")))) -> Em risco | J12: =IF(A12="","",IF(I12="Ativo","Manter relacionamento e oferecer upsell",IF(I12="Em risco","Contato do consultor nesta semana",IF(I12="Inativo","Campanha de reativação","Primeira abordagem comercial")))) -> Contato do consultor nesta semana | K12: =IF(A12="","",G12+ROW()/1000000) -> 16700
A13: Instituto Aprender+ | B13: Rede de ensino | C13: Nordeste | D13: Carla Mendes | E13: =IF(A13="","",IF(F13=0,"",_xlfn.MAXIFS(op_Fech,op_Cliente,A13,op_Status,"Ganha"))) -> 46216 | F13: =IF(A13="","",COUNTIFS(op_Cliente,A13,op_Status,"Ganha")) -> 7 | G13: =IF(A13="","",SUMIFS(op_Valor,op_Cliente,A13,op_Status,"Ganha")) -> 262100 | H13: =IF(OR(A13="",E13=""),"",DataRef-E13) -> 92 | I13: =IF(A13="","",IF(F13=0,"Sem compra",IF(H13<=DiasRisco,"Ativo",IF(H13<=DiasInativo,"Em risco","Inativo")))) -> Em risco | J13: =IF(A13="","",IF(I13="Ativo","Manter relacionamento e oferecer upsell",IF(I13="Em risco","Contato do consultor nesta semana",IF(I13="Inativo","Campanha de reativação","Primeira abordagem comercial")))) -> Contato do consultor nesta semana | K13: =IF(A13="","",G13+ROW()/1000000) -> 262100
A14: Colégio Maristela | B14: Escola privada | C14: Sudeste | D14: Diego Rocha | E14: =IF(A14="","",IF(F14=0,"",_xlfn.MAXIFS(op_Fech,op_Cliente,A14,op_Status,"Ganha"))) -> 46254 | F14: =IF(A14="","",COUNTIFS(op_Cliente,A14,op_Status,"Ganha")) -> 5 | G14: =IF(A14="","",SUMIFS(op_Valor,op_Cliente,A14,op_Status,"Ganha")) -> 64300 | H14: =IF(OR(A14="",E14=""),"",DataRef-E14) -> 54 | I14: =IF(A14="","",IF(F14=0,"Sem compra",IF(H14<=DiasRisco,"Ativo",IF(H14<=DiasInativo,"Em risco","Inativo")))) -> Ativo | J14: =IF(A14="","",IF(I14="Ativo","Manter relacionamento e oferecer upsell",IF(I14="Em risco","Contato do consultor nesta semana",IF(I14="Inativo","Campanha de reativação","Primeira abordagem comercial")))) -> Manter relacionamento e oferecer upsell | K14: =IF(A14="","",G14+ROW()/1000000) -> 64300
A15: Escola Caminho do Saber | B15: Escola privada | C15: Centro-Oeste | D15: Elisa Prado | E15: =IF(A15="","",IF(F15=0,"",_xlfn.MAXIFS(op_Fech,op_Cliente,A15,op_Status,"Ganha"))) -> 46226 | F15: =IF(A15="","",COUNTIFS(op_Cliente,A15,op_Status,"Ganha")) -> 6 | G15: =IF(A15="","",SUMIFS(op_Valor,op_Cliente,A15,op_Status,"Ganha")) -> 98000 | H15: =IF(OR(A15="",E15=""),"",DataRef-E15) -> 82 | I15: =IF(A15="","",IF(F15=0,"Sem compra",IF(H15<=DiasRisco,"Ativo",IF(H15<=DiasInativo,"Em risco","Inativo")))) -> Ativo | J15: =IF(A15="","",IF(I15="Ativo","Manter relacionamento e oferecer upsell",IF(I15="Em risco","Contato do consultor nesta semana",IF(I15="Inativo","Campanha de reativação","Primeira abordagem comercial")))) -> Manter relacionamento e oferecer upsell | K15: =IF(A15="","",G15+ROW()/1000000) -> 98000
A16: Prefeitura de Vila Nova | B16: Prefeitura | C16: Norte | D16: Felipe Duarte | E16: =IF(A16="","",IF(F16=0,"",_xlfn.MAXIFS(op_Fech,op_Cliente,A16,op_Status,"Ganha"))) -> 46262 | F16: =IF(A16="","",COUNTIFS(op_Cliente,A16,op_Status,"Ganha")) -> 1 | G16: =IF(A16="","",SUMIFS(op_Valor,op_Cliente,A16,op_Status,"Ganha")) -> 71200 | H16: =IF(OR(A16="",E16=""),"",DataRef-E16) -> 46 | I16: =IF(A16="","",IF(F16=0,"Sem compra",IF(H16<=DiasRisco,"Ativo",IF(H16<=DiasInativo,"Em risco","Inativo")))) -> Ativo | J16: =IF(A16="","",IF(I16="Ativo","Manter relacionamento e oferecer upsell",IF(I16="Em risco","Contato do consultor nesta semana",IF(I16="Inativo","Campanha de reativação","Primeira abordagem comercial")))) -> Manter relacionamento e oferecer upsell | K16: =IF(A16="","",G16+ROW()/1000000) -> 71200
... A36: Colégio Nova Geração | B36: Escola privada | C36: Sul | D36: Bruno Lima | E36: =IF(A36="","",IF(F36=0,"",_xlfn.MAXIFS(op_Fech,op_Cliente,A36,op_Status,"Ganha"))) | F36: =IF(A36="","",COUNTIFS(op_Cliente,A36,op_Status,"Ganha")) -> 0 | G36: =IF(A36="","",SUMIFS(op_Valor,op_Cliente,A36,op_Status,"Ganha")) -> 0 | H36: =IF(OR(A36="",E36=""),"",DataRef-E36) | I36: =IF(A36="","",IF(F36=0,"Sem compra",IF(H36<=DiasRisco,"Ativo",IF(H36<=DiasInativo,"Em risco","Inativo")))) -> Sem compra | J36: =IF(A36="","",IF(I36="Ativo","Manter relacionamento e oferecer upsell",IF(I36="Em risco","Contato do consultor nesta semana",IF(I36="Inativo","Campanha de reativação","Primeira abordagem comercial")))) -> Primeira abordagem comercial | K36: =IF(A36="","",G36+ROW()/1000000) -> 3.6e-05
E37: =IF(A37="","",IF(F37=0,"",_xlfn.MAXIFS(op_Fech,op_Cliente,A37,op_Status,"Ganha"))) | F37: =IF(A37="","",COUNTIFS(op_Cliente,A37,op_Status,"Ganha")) | G37: =IF(A37="","",SUMIFS(op_Valor,op_Cliente,A37,op_Status,"Ganha")) | H37: =IF(OR(A37="",E37=""),"",DataRef-E37) | I37: =IF(A37="","",IF(F37=0,"Sem compra",IF(H37<=DiasRisco,"Ativo",IF(H37<=DiasInativo,"Em risco","Inativo")))) | J37: =IF(A37="","",IF(I37="Ativo","Manter relacionamento e oferecer upsell",IF(I37="Em risco","Contato do consultor nesta semana",IF(I37="Inativo","Campanha de reativação","Primeira abordagem comercial")))) | K37: =IF(A37="","",G37+ROW()/1000000)
E38: =IF(A38="","",IF(F38=0,"",_xlfn.MAXIFS(op_Fech,op_Cliente,A38,op_Status,"Ganha"))) | F38: =IF(A38="","",COUNTIFS(op_Cliente,A38,op_Status,"Ganha")) | G38: =IF(A38="","",SUMIFS(op_Valor,op_Cliente,A38,op_Status,"Ganha")) | H38: =IF(OR(A38="",E38=""),"",DataRef-E38) | I38: =IF(A38="","",IF(F38=0,"Sem compra",IF(H38<=DiasRisco,"Ativo",IF(H38<=DiasInativo,"Em risco","Inativo")))) | J38: =IF(A38="","",IF(I38="Ativo","Manter relacionamento e oferecer upsell",IF(I38="Em risco","Contato do consultor nesta semana",IF(I38="Inativo","Campanha de reativação","Primeira abordagem comercial")))) | K38: =IF(A38="","",G38+ROW()/1000000)
E39: =IF(A39="","",IF(F39=0,"",_xlfn.MAXIFS(op_Fech,op_Cliente,A39,op_Status,"Ganha"))) | F39: =IF(A39="","",COUNTIFS(op_Cliente,A39,op_Status,"Ganha")) | G39: =IF(A39="","",SUMIFS(op_Valor,op_Cliente,A39,op_Status,"Ganha")) | H39: =IF(OR(A39="",E39=""),"",DataRef-E39) | I39: =IF(A39="","",IF(F39=0,"Sem compra",IF(H39<=DiasRisco,"Ativo",IF(H39<=DiasInativo,"Em risco","Inativo")))) | J39: =IF(A39="","",IF(I39="Ativo","Manter relacionamento e oferecer upsell",IF(I39="Em risco","Contato do consultor nesta semana",IF(I39="Inativo","Campanha de reativação","Primeira abordagem comercial")))) | K39: =IF(A39="","",G39+ROW()/1000000)
E40: =IF(A40="","",IF(F40=0,"",_xlfn.MAXIFS(op_Fech,op_Cliente,A40,op_Status,"Ganha"))) | F40: =IF(A40="","",COUNTIFS(op_Cliente,A40,op_Status,"Ganha")) | G40: =IF(A40="","",SUMIFS(op_Valor,op_Cliente,A40,op_Status,"Ganha")) | H40: =IF(OR(A40="",E40=""),"",DataRef-E40) | I40: =IF(A40="","",IF(F40=0,"Sem compra",IF(H40<=DiasRisco,"Ativo",IF(H40<=DiasInativo,"Em risco","Inativo")))) | J40: =IF(A40="","",IF(I40="Ativo","Manter relacionamento e oferecer upsell",IF(I40="Em risco","Contato do consultor nesta semana",IF(I40="Inativo","Campanha de reativação","Primeira abordagem comercial")))) | K40: =IF(A40="","",G40+ROW()/1000000)
E41: =IF(A41="","",IF(F41=0,"",_xlfn.MAXIFS(op_Fech,op_Cliente,A41,op_Status,"Ganha"))) | F41: =IF(A41="","",COUNTIFS(op_Cliente,A41,op_Status,"Ganha")) | G41: =IF(A41="","",SUMIFS(op_Valor,op_Cliente,A41,op_Status,"Ganha")) | H41: =IF(OR(A41="",E41=""),"",DataRef-E41) | I41: =IF(A41="","",IF(F41=0,"Sem compra",IF(H41<=DiasRisco,"Ativo",IF(H41<=DiasInativo,"Em risco","Inativo")))) | J41: =IF(A41="","",IF(I41="Ativo","Manter relacionamento e oferecer upsell",IF(I41="Em risco","Contato do consultor nesta semana",IF(I41="Inativo","Campanha de reativação","Primeira abordagem comercial")))) | K41: =IF(A41="","",G41+ROW()/1000000)
E42: =IF(A42="","",IF(F42=0,"",_xlfn.MAXIFS(op_Fech,op_Cliente,A42,op_Status,"Ganha"))) | F42: =IF(A42="","",COUNTIFS(op_Cliente,A42,op_Status,"Ganha")) | G42: =IF(A42="","",SUMIFS(op_Valor,op_Cliente,A42,op_Status,"Ganha")) | H42: =IF(OR(A42="",E42=""),"",DataRef-E42) | I42: =IF(A42="","",IF(F42=0,"Sem compra",IF(H42<=DiasRisco,"Ativo",IF(H42<=DiasInativo,"Em risco","Inativo")))) | J42: =IF(A42="","",IF(I42="Ativo","Manter relacionamento e oferecer upsell",IF(I42="Em risco","Contato do consultor nesta semana",IF(I42="Inativo","Campanha de reativação","Primeira abordagem comercial")))) | K42: =IF(A42="","",G42+ROW()/1000000)
E43: =IF(A43="","",IF(F43=0,"",_xlfn.MAXIFS(op_Fech,op_Cliente,A43,op_Status,"Ganha"))) | F43: =IF(A43="","",COUNTIFS(op_Cliente,A43,op_Status,"Ganha")) | G43: =IF(A43="","",SUMIFS(op_Valor,op_Cliente,A43,op_Status,"Ganha")) | H43: =IF(OR(A43="",E43=""),"",DataRef-E43) | I43: =IF(A43="","",IF(F43=0,"Sem compra",IF(H43<=DiasRisco,"Ativo",IF(H43<=DiasInativo,"Em risco","Inativo")))) | J43: =IF(A43="","",IF(I43="Ativo","Manter relacionamento e oferecer upsell",IF(I43="Em risco","Contato do consultor nesta semana",IF(I43="Inativo","Campanha de reativação","Primeira abordagem comercial")))) | K43: =IF(A43="","",G43+ROW()/1000000)
E44: =IF(A44="","",IF(F44=0,"",_xlfn.MAXIFS(op_Fech,op_Cliente,A44,op_Status,"Ganha"))) | F44: =IF(A44="","",COUNTIFS(op_Cliente,A44,op_Status,"Ganha")) | G44: =IF(A44="","",SUMIFS(op_Valor,op_Cliente,A44,op_Status,"Ganha")) | H44: =IF(OR(A44="",E44=""),"",DataRef-E44) | I44: =IF(A44="","",IF(F44=0,"Sem compra",IF(H44<=DiasRisco,"Ativo",IF(H44<=DiasInativo,"Em risco","Inativo")))) | J44: =IF(A44="","",IF(I44="Ativo","Manter relacionamento e oferecer upsell",IF(I44="Em risco","Contato do consultor nesta semana",IF(I44="Inativo","Campanha de reativação","Primeira abordagem comercial")))) | K44: =IF(A44="","",G44+ROW()/1000000)
E45: =IF(A45="","",IF(F45=0,"",_xlfn.MAXIFS(op_Fech,op_Cliente,A45,op_Status,"Ganha"))) | F45: =IF(A45="","",COUNTIFS(op_Cliente,A45,op_Status,"Ganha")) | G45: =IF(A45="","",SUMIFS(op_Valor,op_Cliente,A45,op_Status,"Ganha")) | H45: =IF(OR(A45="",E45=""),"",DataRef-E45) | I45: =IF(A45="","",IF(F45=0,"Sem compra",IF(H45<=DiasRisco,"Ativo",IF(H45<=DiasInativo,"Em risco","Inativo")))) | J45: =IF(A45="","",IF(I45="Ativo","Manter relacionamento e oferecer upsell",IF(I45="Em risco","Contato do consultor nesta semana",IF(I45="Inativo","Campanha de reativação","Primeira abordagem comercial")))) | K45: =IF(A45="","",G45+ROW()/1000000)
E46: =IF(A46="","",IF(F46=0,"",_xlfn.MAXIFS(op_Fech,op_Cliente,A46,op_Status,"Ganha"))) | F46: =IF(A46="","",COUNTIFS(op_Cliente,A46,op_Status,"Ganha")) | G46: =IF(A46="","",SUMIFS(op_Valor,op_Cliente,A46,op_Status,"Ganha")) | H46: =IF(OR(A46="",E46=""),"",DataRef-E46) | I46: =IF(A46="","",IF(F46=0,"Sem compra",IF(H46<=DiasRisco,"Ativo",IF(H46<=DiasInativo,"Em risco","Inativo")))) | J46: =IF(A46="","",IF(I46="Ativo","Manter relacionamento e oferecer upsell",IF(I46="Em risco","Contato do consultor nesta semana",IF(I46="Inativo","Campanha de reativação","Primeira abordagem comercial")))) | K46: =IF(A46="","",G46+ROW()/1000000)
E47: =IF(A47="","",IF(F47=0,"",_xlfn.MAXIFS(op_Fech,op_Cliente,A47,op_Status,"Ganha"))) | F47: =IF(A47="","",COUNTIFS(op_Cliente,A47,op_Status,"Ganha")) | G47: =IF(A47="","",SUMIFS(op_Valor,op_Cliente,A47,op_Status,"Ganha")) | H47: =IF(OR(A47="",E47=""),"",DataRef-E47) | I47: =IF(A47="","",IF(F47=0,"Sem compra",IF(H47<=DiasRisco,"Ativo",IF(H47<=DiasInativo,"Em risco","Inativo")))) | J47: =IF(A47="","",IF(I47="Ativo","Manter relacionamento e oferecer upsell",IF(I47="Em risco","Contato do consultor nesta semana",IF(I47="Inativo","Campanha de reativação","Primeira abordagem comercial")))) | K47: =IF(A47="","",G47+ROW()/1000000)
E48: =IF(A48="","",IF(F48=0,"",_xlfn.MAXIFS(op_Fech,op_Cliente,A48,op_Status,"Ganha"))) | F48: =IF(A48="","",COUNTIFS(op_Cliente,A48,op_Status,"Ganha")) | G48: =IF(A48="","",SUMIFS(op_Valor,op_Cliente,A48,op_Status,"Ganha")) | H48: =IF(OR(A48="",E48=""),"",DataRef-E48) | I48: =IF(A48="","",IF(F48=0,"Sem compra",IF(H48<=DiasRisco,"Ativo",IF(H48<=DiasInativo,"Em risco","Inativo")))) | J48: =IF(A48="","",IF(I48="Ativo","Manter relacionamento e oferecer upsell",IF(I48="Em risco","Contato do consultor nesta semana",IF(I48="Inativo","Campanha de reativação","Primeira abordagem comercial")))) | K48: =IF(A48="","",G48+ROW()/1000000)
... E104: =IF(A104="","",IF(F104=0,"",_xlfn.MAXIFS(op_Fech,op_Cliente,A104,op_Status,"Ganha"))) | F104: =IF(A104="","",COUNTIFS(op_Cliente,A104,op_Status,"Ganha")) | G104: =IF(A104="","",SUMIFS(op_Valor,op_Cliente,A104,op_Status,"Ganha")) | H104: =IF(OR(A104="",E104=""),"",DataRef-E104) | I104: =IF(A104="","",IF(F104=0,"Sem compra",IF(H104<=DiasRisco,"Ativo",IF(H104<=DiasInativo,"Em risco","Inativo")))) | J104: =IF(A104="","",IF(I104="Ativo","Manter relacionamento e oferecer upsell",IF(I104="Em risco","Contato do consultor nesta semana",IF(I104="Inativo","Campanha de reativação","Primeira abordagem comercial")))) | K104: =IF(A104="","",G104+ROW()/1000000)

Sheet Parâmetros
B1: Parâmetros
B2: Valores que alimentam as fórmulas. Texto azul = digitado por você. Fundo amarelo = o que você mais vai mexer.
B4: Parâmetros gerais
B5: Data de referência | C5: 46308 | E5: Fixa para o painel não mudar sozinho. Troque por =HOJE() para uso diário.
B6: Oportunidade parada a partir de (dias em aberto) | C6: 45 | E6: Oportunidade aberta há mais dias que isso recebe o alerta Parada.
B7: Cliente em risco a partir de (dias sem compra) | C7: 90 | E7: Contados desde a última venda ganha.
B8: Cliente inativo a partir de (dias sem compra) | C8: 180 | E8: Acima disso a carteira sugere campanha de reativação.
B10: Auxiliares (calculados, não editar)
B11: Critério do filtro de consultor | C11: =IF(Painel!$F$4="Todos","*",Painel!$F$4) -> * | E11: Vira * (qualquer consultor) quando o Painel está em Todos.
B12: Início do mês selecionado | C12: =Painel!$C$4 -> 46266
B13: Fim do mês selecionado | C13: =EOMONTH(C12,0) -> 46295
B15: Listas
B16: Etapa do funil | C16: Probabilidade | E16: Consultores | G16: Produtos | I16: Regiões | K16: Segmentos | M16: Mês (data) | N16: Rótulo
B17: Prospecção | C17: 0.1 | E17: Todos | G17: Coleção Didática | I17: Sudeste | K17: Escola privada | M17: 46023 | N17: Jan/26
B18: Qualificação | C18: 0.25 | E18: Ana Souza | G18: Plataforma Digital | I18: Sul | K18: Rede de ensino | M18: 46054 | N18: Fev/26
B19: Proposta enviada | C19: 0.5 | E19: Bruno Lima | G19: Material Complementar | I19: Nordeste | K19: Prefeitura | M19: 46082 | N19: Mar/26
B20: Negociação | C20: 0.75 | E20: Carla Mendes | G20: Formação de Professores | I20: Centro-Oeste | K20: Cursinho | M20: 46113 | N20: Abr/26
B21: Fechado ganho | C21: 1 | E21: Diego Rocha | I21: Norte | M21: 46143 | N21: Mai/26
B22: Fechado perdido | C22: 0 | E22: Elisa Prado | M22: 46174 | N22: Jun/26
E23: Felipe Duarte | M23: 46204 | N23: Jul/26
B24: Probabilidades por etapa são ilustrativas. Ajuste ao histórico de conversão da sua equipe. | M24: 46235 | N24: Ago/26
M25: 46266 | N25: Set/26
M26: 46296 | N26: Out/26
M27: 46327 | N27: Nov/26
M28: 46357 | N28: Dez/26
